2020-12-01 21:37:41,936 ERROR: Exception on /index [POST] [in /home/portfolio/venv/lib/python3.8/site-packages/flask/app.py:1891]
Traceback (most recent call last):
  File "/home/portfolio/venv/lib/python3.8/site-packages/flask/app.py", line 2447, in wsgi_app
    response = self.full_dispatch_request()
  File "/home/portfolio/venv/lib/python3.8/site-packages/flask/app.py", line 1952, in full_dispatch_request
    rv = self.handle_user_exception(e)
  File "/home/portfolio/venv/lib/python3.8/site-packages/flask/app.py", line 1821, in handle_user_exception
    reraise(exc_type, exc_value, tb)
  File "/home/portfolio/venv/lib/python3.8/site-packages/flask/_compat.py", line 39, in reraise
    raise value
  File "/home/portfolio/venv/lib/python3.8/site-packages/flask/app.py", line 1950, in full_dispatch_request
    rv = self.dispatch_request()
  File "/home/portfolio/venv/lib/python3.8/site-packages/flask/app.py", line 1936, in dispatch_request
    return self.view_functions[rule.endpoint](**req.view_args)
  File "/home/portfolio/venv/lib/python3.8/site-packages/flask_login/utils.py", line 272, in decorated_view
    return func(*args, **kwargs)
  File "/home/portfolio/ui/client/routes.py", line 28, in index
    pred_id += 1
UnboundLocalError: local variable 'pred_id' referenced before assignment
2020-12-01 21:38:12,763 INFO: NWE startup [in /home/portfolio/ui/client/__init__.py:48]
2020-12-01 21:39:00,138 INFO: NWE startup [in /home/portfolio/ui/client/__init__.py:48]
2020-12-01 21:39:00,309 INFO: NWE startup [in /home/portfolio/ui/client/__init__.py:48]
2020-12-01 21:39:00,617 INFO: NWE startup [in /home/portfolio/ui/client/__init__.py:48]
2020-12-01 21:39:00,724 INFO: NWE startup [in /home/portfolio/ui/client/__init__.py:48]
2020-12-01 21:39:06,961 ERROR: Exception on /index [POST] [in /home/portfolio/venv/lib/python3.8/site-packages/flask/app.py:1891]
Traceback (most recent call last):
  File "/home/portfolio/venv/lib/python3.8/site-packages/flask/app.py", line 2447, in wsgi_app
    response = self.full_dispatch_request()
  File "/home/portfolio/venv/lib/python3.8/site-packages/flask/app.py", line 1952, in full_dispatch_request
    rv = self.handle_user_exception(e)
  File "/home/portfolio/venv/lib/python3.8/site-packages/flask/app.py", line 1821, in handle_user_exception
    reraise(exc_type, exc_value, tb)
  File "/home/portfolio/venv/lib/python3.8/site-packages/flask/_compat.py", line 39, in reraise
    raise value
  File "/home/portfolio/venv/lib/python3.8/site-packages/flask/app.py", line 1950, in full_dispatch_request
    rv = self.dispatch_request()
  File "/home/portfolio/venv/lib/python3.8/site-packages/flask/app.py", line 1936, in dispatch_request
    return self.view_functions[rule.endpoint](**req.view_args)
  File "/home/portfolio/venv/lib/python3.8/site-packages/flask_login/utils.py", line 272, in decorated_view
    return func(*args, **kwargs)
  File "/home/portfolio/ui/client/routes.py", line 28, in index
    self.pred_id += 1
NameError: name 'self' is not defined
2020-12-01 21:39:37,910 INFO: NWE startup [in /home/portfolio/ui/client/__init__.py:48]
2020-12-01 21:41:24,279 INFO: NWE startup [in /home/portfolio/ui/client/__init__.py:48]
2020-12-01 21:41:24,560 INFO: NWE startup [in /home/portfolio/ui/client/__init__.py:48]
2020-12-01 21:41:24,723 INFO: NWE startup [in /home/portfolio/ui/client/__init__.py:48]
2020-12-01 21:41:24,888 INFO: NWE startup [in /home/portfolio/ui/client/__init__.py:48]
2020-12-01 21:41:30,147 ERROR: Exception on /index [POST] [in /home/portfolio/venv/lib/python3.8/site-packages/flask/app.py:1891]
Traceback (most recent call last):
  File "/home/portfolio/venv/lib/python3.8/site-packages/flask/app.py", line 2447, in wsgi_app
    response = self.full_dispatch_request()
  File "/home/portfolio/venv/lib/python3.8/site-packages/flask/app.py", line 1952, in full_dispatch_request
    rv = self.handle_user_exception(e)
  File "/home/portfolio/venv/lib/python3.8/site-packages/flask/app.py", line 1821, in handle_user_exception
    reraise(exc_type, exc_value, tb)
  File "/home/portfolio/venv/lib/python3.8/site-packages/flask/_compat.py", line 39, in reraise
    raise value
  File "/home/portfolio/venv/lib/python3.8/site-packages/flask/app.py", line 1950, in full_dispatch_request
    rv = self.dispatch_request()
  File "/home/portfolio/venv/lib/python3.8/site-packages/flask/app.py", line 1936, in dispatch_request
    return self.view_functions[rule.endpoint](**req.view_args)
  File "/home/portfolio/venv/lib/python3.8/site-packages/flask_login/utils.py", line 272, in decorated_view
    return func(*args, **kwargs)
TypeError: index() missing 1 required positional argument: 'self'
2020-12-01 21:41:33,741 ERROR: Exception on /index [GET] [in /home/portfolio/venv/lib/python3.8/site-packages/flask/app.py:1891]
Traceback (most recent call last):
  File "/home/portfolio/venv/lib/python3.8/site-packages/flask/app.py", line 2447, in wsgi_app
    response = self.full_dispatch_request()
  File "/home/portfolio/venv/lib/python3.8/site-packages/flask/app.py", line 1952, in full_dispatch_request
    rv = self.handle_user_exception(e)
  File "/home/portfolio/venv/lib/python3.8/site-packages/flask/app.py", line 1821, in handle_user_exception
    reraise(exc_type, exc_value, tb)
  File "/home/portfolio/venv/lib/python3.8/site-packages/flask/_compat.py", line 39, in reraise
    raise value
  File "/home/portfolio/venv/lib/python3.8/site-packages/flask/app.py", line 1950, in full_dispatch_request
    rv = self.dispatch_request()
  File "/home/portfolio/venv/lib/python3.8/site-packages/flask/app.py", line 1936, in dispatch_request
    return self.view_functions[rule.endpoint](**req.view_args)
  File "/home/portfolio/venv/lib/python3.8/site-packages/flask_login/utils.py", line 272, in decorated_view
    return func(*args, **kwargs)
TypeError: index() missing 1 required positional argument: 'self'
2020-12-01 21:42:05,021 INFO: NWE startup [in /home/portfolio/ui/client/__init__.py:48]
2020-12-01 21:42:50,039 INFO: NWE startup [in /home/portfolio/ui/client/__init__.py:48]
2020-12-01 21:42:50,112 INFO: NWE startup [in /home/portfolio/ui/client/__init__.py:48]
2020-12-01 21:42:50,410 INFO: NWE startup [in /home/portfolio/ui/client/__init__.py:48]
2020-12-01 21:42:50,734 INFO: NWE startup [in /home/portfolio/ui/client/__init__.py:48]
2020-12-01 21:42:57,111 ERROR: Exception on /index [GET] [in /home/portfolio/venv/lib/python3.8/site-packages/flask/app.py:1891]
Traceback (most recent call last):
  File "/home/portfolio/venv/lib/python3.8/site-packages/flask/app.py", line 2447, in wsgi_app
    response = self.full_dispatch_request()
  File "/home/portfolio/venv/lib/python3.8/site-packages/flask/app.py", line 1952, in full_dispatch_request
    rv = self.handle_user_exception(e)
  File "/home/portfolio/venv/lib/python3.8/site-packages/flask/app.py", line 1821, in handle_user_exception
    reraise(exc_type, exc_value, tb)
  File "/home/portfolio/venv/lib/python3.8/site-packages/flask/_compat.py", line 39, in reraise
    raise value
  File "/home/portfolio/venv/lib/python3.8/site-packages/flask/app.py", line 1950, in full_dispatch_request
    rv = self.dispatch_request()
  File "/home/portfolio/venv/lib/python3.8/site-packages/flask/app.py", line 1936, in dispatch_request
    return self.view_functions[rule.endpoint](**req.view_args)
  File "/home/portfolio/venv/lib/python3.8/site-packages/flask_login/utils.py", line 272, in decorated_view
    return func(*args, **kwargs)
TypeError: index() missing 1 required positional argument: 'pred_id'
2020-12-01 21:43:27,960 INFO: NWE startup [in /home/portfolio/ui/client/__init__.py:48]
2020-12-01 21:48:37,442 INFO: NWE startup [in /home/portfolio/ui/client/__init__.py:48]
2020-12-01 21:48:37,506 INFO: NWE startup [in /home/portfolio/ui/client/__init__.py:48]
2020-12-01 21:48:37,905 INFO: NWE startup [in /home/portfolio/ui/client/__init__.py:48]
2020-12-01 21:48:38,080 INFO: NWE startup [in /home/portfolio/ui/client/__init__.py:48]
2020-12-01 21:54:22,473 INFO: NWE startup [in /home/portfolio/ui/client/__init__.py:48]
2020-12-01 21:54:22,840 INFO: NWE startup [in /home/portfolio/ui/client/__init__.py:48]
2020-12-01 21:54:22,971 INFO: NWE startup [in /home/portfolio/ui/client/__init__.py:48]
2020-12-01 21:54:23,308 INFO: NWE startup [in /home/portfolio/ui/client/__init__.py:48]
2020-12-01 21:54:27,014 ERROR: Exception on /index [GET] [in /home/portfolio/venv/lib/python3.8/site-packages/flask/app.py:1891]
Traceback (most recent call last):
  File "/home/portfolio/venv/lib/python3.8/site-packages/flask/app.py", line 2447, in wsgi_app
    response = self.full_dispatch_request()
  File "/home/portfolio/venv/lib/python3.8/site-packages/flask/app.py", line 1952, in full_dispatch_request
    rv = self.handle_user_exception(e)
  File "/home/portfolio/venv/lib/python3.8/site-packages/flask/app.py", line 1821, in handle_user_exception
    reraise(exc_type, exc_value, tb)
  File "/home/portfolio/venv/lib/python3.8/site-packages/flask/_compat.py", line 39, in reraise
    raise value
  File "/home/portfolio/venv/lib/python3.8/site-packages/flask/app.py", line 1950, in full_dispatch_request
    rv = self.dispatch_request()
  File "/home/portfolio/venv/lib/python3.8/site-packages/flask/app.py", line 1936, in dispatch_request
    return self.view_functions[rule.endpoint](**req.view_args)
  File "/home/portfolio/venv/lib/python3.8/site-packages/flask_login/utils.py", line 272, in decorated_view
    return func(*args, **kwargs)
  File "/home/portfolio/ui/client/routes.py", line 27, in index
    pred_id += 1
TypeError: can only concatenate str (not "int") to str
2020-12-01 21:54:57,463 INFO: NWE startup [in /home/portfolio/ui/client/__init__.py:48]
2020-12-01 21:58:54,336 INFO: NWE startup [in /home/portfolio/ui/client/__init__.py:49]
2020-12-01 21:58:54,527 INFO: NWE startup [in /home/portfolio/ui/client/__init__.py:49]
2020-12-01 21:58:54,644 INFO: NWE startup [in /home/portfolio/ui/client/__init__.py:49]
2020-12-01 21:58:54,981 INFO: NWE startup [in /home/portfolio/ui/client/__init__.py:49]
2020-12-01 21:59:18,058 INFO: NWE startup [in /home/portfolio/ui/client/__init__.py:49]
